Workbook

Sheet DASHBOARD CRM Royalty Program
A1: Dashboard Evaluasi Program CRM Loyalty Periode Jun-Sep 2026
A4: Transaksi | D4: Total Belanja | G4: Redemption Berhasil | J4: Rata-Rata Per Transaksi
A5: =GETPIVOTDATA("jumlah transaksi",Analisa!$A$9) -> 820 | D5: =Analisa!B18 -> 248370007 | G5: =GETPIVOTDATA("RedemptionID",Analisa!$D$9,"Years (Tanggal)",2026) -> 222 | J5: =Analisa!B21 -> 302890.25
A6: ="Target: "&Analisa!D17 -> Target: 1100 | D6: ="Target: Rp" &Analisa!D18 -> Target: Rp192000000 | G6: ="Target: "&Analisa!D19 -> Target: 390 | J6: ="Target: Rp" &ROUND(Analisa!B22,0) -> Target: Rp174545
A7: ="Pencapaian: "&ROUND(Analisa!F17*100,1)&"%" -> Pencapaian: 74,5% | D7: ="Pencapaian: "&ROUND(Analisa!F18*100,1)&"%" -> Pencapaian: 129,4% | G7: ="Pencapaian: "&ROUND(Analisa!F19*100,1)&"%" -> Pencapaian: 56,9% | J7: ="Pencapaian: "&ROUNDUP(Analisa!B23*100,0)&"%" -> Pencapaian: 74%
A9: Insight Utama
A11: ="Transaksi "&ROUND(Analisa!F17*100,1)&"% dari target dan redemption "&ROUND('DASHBOARD CRM Royalty Program'!F19*100,1)&"%, sedangkan total belanja "&ROUND(Analisa!F18*100,1)&"% dari target karena rata-rata nominal per transaksi sebesar Rp"&FIXED(Analisa!B21,0) -> Transaksi 74,5% dari target dan redemption 0%, sedangkan total belanja 129,4% dari target karena rata-rata nominal per transaksi sebesar Rp302.890
A12: ="Tier "&ROUND(Analisa!E36*100,1)&"% dari total belanja dan rata-rata nominal tertinggi ada di kategori Platinum Rp. "&ROUND(GETPIVOTDATA("Rata-rata Belanja",Analisa!$A$33,"Tier","Platinum"),0)&", sedangkan yang terendah di tier Silver Rp. "&ROUND(GETPIVOTDATA("Rata-rata Belanja",Analisa!$A$33,"Tier","Silver"),0)&" - Peluang Upsell/Bundling" -> Tier 58,1% dari total belanja dan rata-rata nominal tertinggi ada di kategori Platinum Rp. 331985, sedangkan yang terendah di tier Silver Rp. 291469 - Peluang Upsell/Bundling
A13: =Analisa!B67 -> 1 reward harus segera restock ( voucher belanja Rp.200.000 ) karena estimasi habisnya dibawah 6 bulan, dan sisanya ada 6 reward yang harus dievaluasi karena stock berlebih
A14: ="Kategori dengan total belanja tertinggi adalah Fashion sebesar Rp. "& ROUND(GETPIVOTDATA("Sum of NominalBelanja",Analisa!$A$78,"Kategori","Fashion"),0)&" dengan 0 patner aktif dan 1 prospek ( Zalora). Jumlah transaksi antar kategori relatif merata" -> Kategori dengan total belanja tertinggi adalah Fashion sebesar Rp. 43955911 dengan 0 patner aktif dan 1 prospek ( Zalora). Jumlah transaksi antar kategori relatif merata

Sheet Analisa
A3: Evaluasi performa program vs target (Jun-Sep 2026)
A5: Jumlah Transaksi Per jun-Sep 2026 | D5: Jumlah redemption per jun-sep 2026 | I5: Total Belanja : Actual vs Target
A6: Years (Tanggal) | B6: 2026 | D6: Status | E6: Berhasil | I6: Bulan | J6: Actual Nominal | K6: TargetNominal
A7: Months (Tanggal) | B7: (Multiple Items) | D7: Months (Tanggal) | E7: (Multiple Items) | I7: Juni | J7: 55419579 | K7: 45000000
I8: Juli | J8: 72011619 | K8: 47000000
A9: jumlah transaksi | B9: total belanja | D9: tahun | E9: Jumlah Redeem | I9: Agustus | J9: 65613055 | K9: 49000000
A10: 820 | B10: 248370007 | D10: 2026 | E10: 222 | I10: September | J10: 55325754 | K10: 51000000
D11: Grand Total | E11: 222
I12: Transaksi : Actual VS Target
I13: Bulan | J13: Actual Transaksi | K13: TargetTransaksi
A14: ACTUAL VS TARGET for Jun-Sep 2026 | I14: Juni | J14: 183 | K14: 260
A15: Actual | C15: Target | I15: Juli | J15: 229 | K15: 270
A16: point | B16: nilai | C16: point | D16: nilai | E16: GAP | F16: Pencapaian | I16: Agustus | J16: 218 | K16: 280
A17: jumlah transaksi | B17: 820 | C17: Transaksi | D17: 1100 | E17: =Table8[[#This Row],[nilai ]]-Table8[[#This Row],[nilai]] -> -280 | F17: =Table8[[#This Row],[nilai ]]/Table8[[#This Row],[nilai]] -> 0.74545455 | I17: September | J17: 190 | K17: 290
A18: total belanja | B18: 248370007 | C18: Total Belanja | D18: 192000000 | E18: =Table8[[#This Row],[nilai ]]-Table8[[#This Row],[nilai]] -> 56370007 | F18: =Table8[[#This Row],[nilai ]]/Table8[[#This Row],[nilai]] -> 1.2935938 | I18: redeem actual vs target
A19: jumlah redeem | B19: 222 | C19: Redemption | D19: 390 | E19: =Table8[[#This Row],[nilai ]]-Table8[[#This Row],[nilai]] -> -168 | F19: =Table8[[#This Row],[nilai ]]/Table8[[#This Row],[nilai]] -> 0.56923077 | I19: Bulan | J19: Actual Redeem | K19: Actual Nominal
I20: Juni | J20: 47 | K20: 90
A21: Rata- rata nominal per transaksi( actual) | B21: =B18/B17 -> 302890.25 | I21: Juli | J21: 56 | K21: 95
A22: rata- rata nominal per transaksi( target) | B22: =D18/D17 -> 174545.45 | I22: Agustus | J22: 64 | K22: 100
A23: selisih presentase (actual) | B23: =(B21-B22)/B22*100% -> 0.73530874 | I23: September | J23: 55 | K23: 105
A25: Transaksi (75%) dan redemption (57%) belum mencapai target, sedangkan total belanja melampaui target (129%) karena rata-rata nominal per transaksi Rp302.890, sekitar 74% di atas target.
A29: Analisis engagement per tier member (Jun-Sep 2026)
A30: Years (Tanggal) | B30: 2026
A31: Months (Tanggal) | B31: (Multiple Items)
A33: Tier | B33: frekuensi belanja | C33: Rata-rata Belanja | D33: Total Belanja | E33: Presentase
A34: Gold | B34: 247 | C34: 316590.92 | D34: =B34*C34 -> 78197957 | E34: =D34/D37 -> 0.31484461
A35: Platinum | B35: 78 | C35: 331984.82 | D35: =B35*C35 -> 25894816 | E35: =D35/D37 -> 0.10425903
A36: Silver | B36: 495 | C36: 291469.16 | D36: =B36*C36 -> 144277234 | E36: =D36/D37 -> 0.58089636
A37: Grand Total | B37: 820 | C37: 302890.25 | D37: =SUM(D34:D36) -> 248370007
A40: insight
A41: Berdasarkan Data yang dilampirkan, Silver menyumbang porsi terbesar karena jumlah membernya paling banyak. Rata-rata nominalnya paling rendah, dan Platinum paling tinggi. Jadi peluangnya ada di upsell/bundling untuk Silver, dan mendorong Silver naik ke Gold.
A54: Kontrol stok reward
A55: RewardID | B55: NamaReward | C55: StokTersisa | D55: estimasi habis(bulan) | E55: Rekomendasi
A56: RW006 | B56: Free Ongkir 3X | C56: 726 | D56: 117.72973 | E56: {=_xlfn.IFS(D56<=6,"segera restock",D56<=24,"aman",D56>24,"evaluasi")} -> evaluasi
A57: RW005 | B57: Voucher Ojek Online Rp25.000 | C57: 532 | D57: 93.882353 | E57: {=_xlfn.IFS(D57<=6,"segera restock",D57<=24,"aman",D57>24,"evaluasi")} -> evaluasi
A58: RW001 | B58: Voucher Belanja Rp50.000 | C58: 422 | D58: 64.923077 | E58: {=_xlfn.IFS(D58<=6,"segera restock",D58<=24,"aman",D58>24,"evaluasi")} -> evaluasi
A59: RW003 | B59: Diskon 20% F&B Partner | C59: 334 | D59: 60.727273 | E59: {=_xlfn.IFS(D59<=6,"segera restock",D59<=24,"aman",D59>24,"evaluasi")} -> evaluasi
A60: RW002 | B60: Voucher Belanja Rp100.000 | C60: 272 | D60: 41.846154 | E60: {=_xlfn.IFS(D60<=6,"segera restock",D60<=24,"aman",D60>24,"evaluasi")} -> evaluasi
A61: RW008 | B61: Diskon 15% Fashion Partner | C61: 172 | D61: 26.461538 | E61: {=_xlfn.IFS(D61<=6,"segera restock",D61<=24,"aman",D61>24,"evaluasi")} -> evaluasi
A62: RW010 | B62: Voucher Nonton Bioskop | C62: 116 | D62: 21.75 | E62: {=_xlfn.IFS(D62<=6,"segera restock",D62<=24,"aman",D62>24,"evaluasi")} -> aman
...

Sheet Transaksi
A1: TransaksiID | B1: MemberID | C1: Tanggal | D1: Toko | E1: Kategori | F1: NominalBelanja | G1: Tier | H1: PoinDidapat
A2: TX002281 | B2: M0296 | C2: 45952 | D2: Toko H - Denpasar | E2: Groceries | F2: 279317 | G2: =VLOOKUP(Table2[[#This Row],[MemberID]],Table1[#All],3,0) -> Gold | H2: 27
A3: TX000593 | B3: M0082 | C3: 46085 | D3: Toko E - Semarang | E3: F&B | F3: 231334 | G3: =VLOOKUP(Table2[[#This Row],[MemberID]],Table1[#All],3,0) -> Silver | H3: 23
A4: TX002146 | B4: M0276 | C4: 46141 | D4: Toko F - Makassar | E4: Fashion | F4: 586040 | G4: =VLOOKUP(Table2[[#This Row],[MemberID]],Table1[#All],3,0) -> Silver | H4: 58
A5: TX000237 | B5: M0035 | C5: 45977 | D5: Toko D - Medan | E5: F&B | F5: 201461 | G5: =VLOOKUP(Table2[[#This Row],[MemberID]],Table1[#All],3,0) -> Silver | H5: 20
A6: TX001046 | B6: M0134 | C6: 46015 | D6: Toko G - Yogyakarta | E6: Groceries | F6: 404247 | G6: =VLOOKUP(Table2[[#This Row],[MemberID]],Table1[#All],3,0) -> Silver | H6: 40
A7: TX001232 | B7: M0161 | C7: 46228 | D7: Toko H - Denpasar | E7: Electronics | F7: 355497 | G7: =VLOOKUP(Table2[[#This Row],[MemberID]],Table1[#All],3,0) -> Silver | H7: 35
A8: TX001006 | B8: M0128 | C8: 45944 | D8: Toko H - Denpasar | E8: Electronics | F8: 69450 | G8: =VLOOKUP(Table2[[#This Row],[MemberID]],Table1[#All],3,0) -> Silver | H8: 6
A9: TX000920 | B9: M0119 | C9: 45975 | D9: Toko E - Semarang | E9: Home & Living | F9: 233276 | G9: =VLOOKUP(Table2[[#This Row],[MemberID]],Table1[#All],3,0) -> Silver | H9: 23
A10: TX000195 | B10: M0028 | C10: 46240 | D10: Toko H - Denpasar | E10: Health & Beauty | F10: 25000 | G10: =VLOOKUP(Table2[[#This Row],[MemberID]],Table1[#All],3,0) -> Gold | H10: 2
A11: TX000048 | B11: M0003 | C11: 46084 | D11: Toko G - Yogyakarta | E11: Home & Living | F11: 318175 | G11: =VLOOKUP(Table2[[#This Row],[MemberID]],Table1[#All],3,0) -> Gold | H11: 31
A12: TX000259 | B12: M0039 | C12: 46115 | D12: Toko B - Bandung | E12: Health & Beauty | F12: 548410 | G12: =VLOOKUP(Table2[[#This Row],[MemberID]],Table1[#All],3,0) -> Gold | H12: 54
A13: TX001759 | B13: M0233 | C13: 46090 | D13: Toko A - Jakarta | E13: Home & Living | F13: 351666 | G13: =VLOOKUP(Table2[[#This Row],[MemberID]],Table1[#All],3,0) -> Gold | H13: 35
... A2320: TX001062 | B2320: M0137 | C2320: 46032 | D2320: Toko D - Medan | E2320: Electronics | F2320: 589379 | G2320: =VLOOKUP(Table2[[#This Row],[MemberID]],Table1[#All],3,0) -> Gold | H2320: 58

Sheet Redemption
A1: RedemptionID | B1: MemberID | C1: Tanggal | D1: RewardID | E1: NamaReward | F1: PoinDitukar | G1: Status | H1: kecepatan/bulan
A2: RD00001 | B2: M0019 | C2: 46259 | D2: RW009 | E2: Merchandise Tas Belanja Ramah Lingkungan | F2: 3500 | G2: Berhasil
A3: RD00002 | B3: M0080 | C3: 46253 | D3: RW006 | E3: Free Ongkir 3X | F3: 1500 | G3: Berhasil
A4: RD00003 | B4: M0201 | C4: 46259 | D4: RW005 | E4: Voucher Ojek Online Rp25.000 | F4: 2500 | G4: Berhasil
A5: RD00004 | B5: M0057 | C5: 45932 | D5: RW008 | E5: Diskon 15% Fashion Partner | F5: 4000 | G5: Berhasil
A6: RD00005 | B6: M0208 | C6: 46033 | D6: RW003 | E6: Diskon 20% F&B Partner | F6: 3000 | G6: Berhasil
A7: RD00006 | B7: M0267 | C7: 46091 | D7: RW007 | E7: Voucher Belanja Rp200.000 | F7: 20000 | G7: Dibatalkan
A8: RD00007 | B8: M0166 | C8: 45973 | D8: RW006 | E8: Free Ongkir 3X | F8: 1500 | G8: Berhasil
A9: RD00008 | B9: M0067 | C9: 46011 | D9: RW008 | E9: Diskon 15% Fashion Partner | F9: 4000 | G9: Berhasil
A10: RD00009 | B10: M0049 | C10: 46195 | D10: RW007 | E10: Voucher Belanja Rp200.000 | F10: 20000 | G10: Berhasil
A11: RD00010 | B11: M0280 | C11: 46235 | D11: RW005 | E11: Voucher Ojek Online Rp25.000 | F11: 2500 | G11: Berhasil
A12: RD00011 | B12: M0048 | C12: 46094 | D12: RW010 | E12: Voucher Nonton Bioskop | F12: 6000 | G12: Berhasil
A13: RD00012 | B13: M0177 | C13: 46175 | D13: RW001 | E13: Voucher Belanja Rp50.000 | F13: 5000 | G13: Berhasil
... A901: RD00900 | B901: M0219 | C901: 46141 | D901: RW002 | E901: Voucher Belanja Rp100.000 | F901: 10000 | G901: Berhasil

Sheet Reward_Inventory
A1: RewardID | B1: NamaReward | C1: PoinDibutuhkan | D1: StokAwal | E1: JumlahDitukar | F1: StokTersisa | G1: Toko | H1: stok terpakai | I1: kecepatan penukaran | J1: estimasi habis(bulan)
A2: RW007 | B2: Voucher Belanja Rp200.000 | C2: 20000 | D2: 100 | E2: 70 | F2: 30 | G2: Semua Toko | H2: =Table4[[#This Row],[JumlahDitukar]]/Table4[[#This Row],[StokAwal]] -> 0.7 | I2: =Table4[[#This Row],[JumlahDitukar]]/12 -> 5.8333333 | J2: =Table4[[#This Row],[StokTersisa]]/Table4[[#This Row],[kecepatan penukaran]] -> 5.1428571
A3: RW009 | B3: Merchandise Tas Belanja Ramah Lingkungan | C3: 3500 | D3: 200 | E3: 82 | F3: 118 | G3: Semua Toko | H3: =Table4[[#This Row],[JumlahDitukar]]/Table4[[#This Row],[StokAwal]] -> 0.41 | I3: =Table4[[#This Row],[JumlahDitukar]]/12 -> 6.8333333 | J3: =Table4[[#This Row],[StokTersisa]]/Table4[[#This Row],[kecepatan penukaran]] -> 17.268293
A4: RW004 | B4: Merchandise Tumbler Eksklusif | C4: 8000 | D4: 150 | E4: 59 | F4: 91 | G4: Semua Toko | H4: =Table4[[#This Row],[JumlahDitukar]]/Table4[[#This Row],[StokAwal]] -> 0.39333333 | I4: =Table4[[#This Row],[JumlahDitukar]]/12 -> 4.9166667 | J4: =Table4[[#This Row],[StokTersisa]]/Table4[[#This Row],[kecepatan penukaran]] -> 18.508475
A5: RW010 | B5: Voucher Nonton Bioskop | C5: 6000 | D5: 180 | E5: 64 | F5: 116 | G5: Semua Toko | H5: =Table4[[#This Row],[JumlahDitukar]]/Table4[[#This Row],[StokAwal]] -> 0.35555556 | I5: =Table4[[#This Row],[JumlahDitukar]]/12 -> 5.3333333 | J5: =Table4[[#This Row],[StokTersisa]]/Table4[[#This Row],[kecepatan penukaran]] -> 21.75
A6: RW008 | B6: Diskon 15% Fashion Partner | C6: 4000 | D6: 250 | E6: 78 | F6: 172 | G6: Semua Toko | H6: =Table4[[#This Row],[JumlahDitukar]]/Table4[[#This Row],[StokAwal]] -> 0.312 | I6: =Table4[[#This Row],[JumlahDitukar]]/12 -> 6.5 | J6: =Table4[[#This Row],[StokTersisa]]/Table4[[#This Row],[kecepatan penukaran]] -> 26.461538
A7: RW002 | B7: Voucher Belanja Rp100.000 | C7: 10000 | D7: 350 | E7: 78 | F7: 272 | G7: Semua Toko | H7: =Table4[[#This Row],[JumlahDitukar]]/Table4[[#This Row],[StokAwal]] -> 0.22285714 | I7: =Table4[[#This Row],[JumlahDitukar]]/12 -> 6.5 | J7: =Table4[[#This Row],[StokTersisa]]/Table4[[#This Row],[kecepatan penukaran]] -> 41.846154
A8: RW003 | B8: Diskon 20% F&B Partner | C8: 3000 | D8: 400 | E8: 66 | F8: 334 | G8: Semua Toko | H8: =Table4[[#This Row],[JumlahDitukar]]/Table4[[#This Row],[StokAwal]] -> 0.165 | I8: =Table4[[#This Row],[JumlahDitukar]]/12 -> 5.5 | J8: =Table4[[#This Row],[StokTersisa]]/Table4[[#This Row],[kecepatan penukaran]] -> 60.727273
A9: RW001 | B9: Voucher Belanja Rp50.000 | C9: 5000 | D9: 500 | E9: 78 | F9: 422 | G9: Semua Toko | H9: =Table4[[#This Row],[JumlahDitukar]]/Table4[[#This Row],[StokAwal]] -> 0.156 | I9: =Table4[[#This Row],[JumlahDitukar]]/12 -> 6.5 | J9: =Table4[[#This Row],[StokTersisa]]/Table4[[#This Row],[kecepatan penukaran]] -> 64.923077
A10: RW005 | B10: Voucher Ojek Online Rp25.000 | C10: 2500 | D10: 600 | E10: 68 | F10: 532 | G10: Semua Toko | H10: =Table4[[#This Row],[JumlahDitukar]]/Table4[[#This Row],[StokAwal]] -> 0.11333333 | I10: =Table4[[#This Row],[JumlahDitukar]]/12 -> 5.6666667 | J10: =Table4[[#This Row],[StokTersisa]]/Table4[[#This Row],[kecepatan penukaran]] -> 93.882353
A11: RW006 | B11: Free Ongkir 3X | C11: 1500 | D11: 800 | E11: 74 | F11: 726 | G11: Semua Toko | H11: =Table4[[#This Row],[JumlahDitukar]]/Table4[[#This Row],[StokAwal]] -> 0.0925 | I11: =Table4[[#This Row],[JumlahDitukar]]/12 -> 6.1666667 | J11: =Table4[[#This Row],[StokTersisa]]/Table4[[#This Row],[kecepatan penukaran]] -> 117.72973

Sheet Merchant_Partners
A1: PartnerID | B1: NamaPartner | C1: Kategori | D1: Status | E1: Catatan
A2: MP01 | B2: Kopi Kenangan | C2: F&B | D2: Aktif | E2: Diskon 15% untuk member Gold & Platinum
A3: MP02 | B3: Erafone | C3: Electronics | D3: Aktif | E3: Cicilan 0% khusus member
A4: MP03 | B4: Informa | C4: Home & Living | D4: Aktif | E4: Diskon 10% all items
A5: MP04 | B5: CGV Cinemas | C5: Entertainment | D5: Aktif | E5: Buy 1 Get 1 tiket weekday
A6: MP05 | B6: Watsons | C6: Health & Beauty | D6: Aktif | E6: Poin 2x untuk pembelian di atas Rp150rb
A7: MP06 | B7: Gramedia | C7: Books & Stationery | D7: Prospek | E7: Rencana diskon 10% member baru
A8: MP07 | B8: Guardian | C8: Health & Beauty | D8: Prospek | E8: Sedang negosiasi kerja sama poin ganda
A9: MP08 | B9: Zalora | C9: Fashion | D9: Prospek | E9: Rencana cashback poin untuk pembelian online
A10: MP09 | B10: GoFood | C10: F&B | D10: Aktif | E10: Voucher potongan ongkir untuk redemption poin
A11: MP10 | B11: IKEA | C11: Home & Living | D11: Prospek | E11: Rencana bundling reward furniture kecil

Sheet power-query
A1: TransaksiID | B1: MemberID | C1: Tanggal transaksi | D1: Toko | E1: Kategori | F1: NominalBelanja | G1: PoinDidapat | H1: RedemptionID | I1: Tanggal Redeem | J1: RewardID | K1: NamaReward | L1: PoinDitukar | M1: Status
A2: TX002281 | B2: M0296 | C2: 45952 | D2: Toko H - Denpasar | E2: Groceries | F2: 279317 | G2: 27 | H2: RD00049 | I2: 46058 | J2: RW009 | K2: Merchandise Tas Belanja Ramah Lingkungan | L2: 3500 | M2: Berhasil
A3: TX002281 | B3: M0296 | C3: 45952 | D3: Toko H - Denpasar | E3: Groceries | F3: 279317 | G3: 27 | H3: RD00437 | I3: 45943 | J3: RW010 | K3: Voucher Nonton Bioskop | L3: 6000 | M3: Dibatalkan
A4: TX002281 | B4: M0296 | C4: 45952 | D4: Toko H - Denpasar | E4: Groceries | F4: 279317 | G4: 27 | H4: RD00740 | I4: 46064 | J4: RW005 | K4: Voucher Ojek Online Rp25.000 | L4: 2500 | M4: Berhasil
A5: TX002280 | B5: M0296 | C5: 46212 | D5: Toko C - Surabaya | E5: Home & Living | F5: 179586 | G5: 17 | H5: RD00049 | I5: 46058 | J5: RW009 | K5: Merchandise Tas Belanja Ramah Lingkungan | L5: 3500 | M5: Berhasil
A6: TX002280 | B6: M0296 | C6: 46212 | D6: Toko C - Surabaya | E6: Home & Living | F6: 179586 | G6: 17 | H6: RD00437 | I6: 45943 | J6: RW010 | K6: Voucher Nonton Bioskop | L6: 6000 | M6: Dibatalkan
A7: TX002280 | B7: M0296 | C7: 46212 | D7: Toko C - Surabaya | E7: Home & Living | F7: 179586 | G7: 17 | H7: RD00740 | I7: 46064 | J7: RW005 | K7: Voucher Ojek Online Rp25.000 | L7: 2500 | M7: Berhasil
A8: TX000150 | B8: M0019 | C8: 45956 | D8: Toko B - Bandung | E8: Electronics | F8: 117554 | G8: 11 | H8: RD00001 | I8: 46259 | J8: RW009 | K8: Merchandise Tas Belanja Ramah Lingkungan | L8: 3500 | M8: Berhasil
A9: TX000150 | B9: M0019 | C9: 45956 | D9: Toko B - Bandung | E9: Electronics | F9: 117554 | G9: 11 | H9: RD00078 | I9: 45953 | J9: RW004 | K9: Merchandise Tumbler Eksklusif | L9: 8000 | M9: Berhasil
A10: TX000147 | B10: M0019 | C10: 46120 | D10: Toko E - Semarang | E10: Home & Living | F10: 739701 | G10: 73 | H10: RD00001 | I10: 46259 | J10: RW009 | K10: Merchandise Tas Belanja Ramah Lingkungan | L10: 3500 | M10: Berhasil
A11: TX000147 | B11: M0019 | C11: 46120 | D11: Toko E - Semarang | E11: Home & Living | F11: 739701 | G11: 73 | H11: RD00078 | I11: 45953 | J11: RW004 | K11: Merchandise Tumbler Eksklusif | L11: 8000 | M11: Berhasil
A12: TX000593 | B12: M0082 | C12: 46085 | D12: Toko E - Semarang | E12: F&B | F12: 231334 | G12: 23 | H12: RD00841 | I12: 46135 | J12: RW002 | K12: Voucher Belanja Rp100.000 | L12: 10000 | M12: Berhasil
A13: TX000593 | B13: M0082 | C13: 46085 | D13: Toko E - Semarang | E13: F&B | F13: 231334 | G13: 23 | H13: RD00896 | I13: 46267 | J13: RW005 | K13: Voucher Ojek Online Rp25.000 | L13: 2500 | M13: Berhasil
... A6850: TX001062 | B6850: M0137 | C6850: 46032 | D6850: Toko D - Medan | E6850: Electronics | F6850: 589379 | G6850: 58 | H6850: RD00674 | I6850: 46153 | J6850: RW005 | K6850: Voucher Ojek Online Rp25.000 | L6850: 2500 | M6850: Berhasil

Sheet Members
A1: MemberID | B1: Kota | C1: Tier | D1: Tanggal Gabung
A2: M0001 | B2: Semarang | C2: Silver | D2: 45581
A3: M0002 | B3: Bandung | C3: Silver | D3: 45177
A4: M0003 | B4: Bandung | C4: Gold | D4: 45619
A5: M0004 | B5: Jakarta | C5: Silver | D5: 45531
A6: M0005 | B6: Jakarta | C6: Silver | D6: 45022
A7: M0006 | B7: Yogyakarta | C7: Silver | D7: 45501
A8: M0007 | B8: Semarang | C8: Silver | D8: 45152
A9: M0008 | B9: Surabaya | C9: Gold | D9: 45755
A10: M0009 | B10: Semarang | C10: Silver | D10: 45641
A11: M0010 | B11: Makassar | C11: Silver | D11: 45086
A12: M0011 | B12: Bandung | C12: Silver | D12: 45031
A13: M0012 | B13: Semarang | C13: Gold | D13: 45294
... A301: M0300 | B301: Medan | C301: Silver | D301: 45051

Sheet Target_Program
A1: Bulan | B1: TargetTransaksi | C1: TargetNominal | D1: TargetRedemption
A2: 2026-06 | B2: 260 | C2: 45000000 | D2: 90
A3: 2026-07 | B3: 270 | C3: 47000000 | D3: 95
A4: 2026-08 | B4: 280 | C4: 49000000 | D4: 100
A5: 2026-09 | B5: 290 | C5: 51000000 | D5: 105
B6: =SUM(B2:B5) -> 1100 | C6: =SUM(C2:C5) -> 192000000 | D6: =SUM(D2:D5) -> 390
